Workbook

Sheet INDICE
B5: ÍNDICE
A7: 1 | B7: Cálculo SSFV Strings a Inversor
A8: 2 | B8: Cálculo SSFV Salida del inversor - Tablero AC
A9: 3 | B9: Cálculo SSFV Tablero AC - Punto de Interconexión cliente
A10: 4 | B10: Cálculo regulación de Voltaje
A11: 5 | B11: Pérdidas de energia en el SSFV
A12: 6 | B12: Cálculo caida de tensión en el SSFV
A13: 7 | B13: Tabla auxiliar información ficha técnica de tuberia
A14: 8 | B14: Tabla auxiliar información ficha técnica de bandeja portacable
A15: 9 | B15: Tabla auxiliar conversión áreas de cableado
A16: 10 | B16: NTC 2050 Tabla 310-16
A17: 11 | B17: NTC 2050 Puesta a tierra
A18: 12 | B18: NTC 2050 Tabla auxiliar para cálculo de conductores
... A23: 17 | B23: Variables del sistema en la mémoria de cálculo

Sheet PV_INV_STRING
A1: Información de módulos solares fotovoltaicos | H1: Casillas de control
A2: Parametro | B2: Valor | H2: =IF(AND(B19>=21,B19<=25),"21-25",IF(AND(B19>=26,B19<=30),"26-30",IF(AND(B19>=31,B19<=35),"31-35",IF(AND(B19>=36,B19<=40),"36-40",IF(AND(B19>=41,B19<=45),"41-45",IF(AND(B19>=46,B19<=50),"46-50",IF(AND(B19>=51,B19<=55),"51-55",IF(AND(B19>=56,B19<=60),"56-60",IF(AND(B19>=61,B19<=70),"61-70",IF(AND(B19>=71,B19<=80),"71-80","ERROR")))))))))) -> 21-25
A3: Fabricante | B3: Longi | H3: =IF(AND(B23>=1,B23<=3),1,IF(AND(B23>=4,B23<=6),"De 4 a 6",IF(AND(B23>=7,B23<=9),"De 7 a 9",IF(AND(B23>=10,B23<=20),"De 10 a 20",IF(AND(B23>=21,B23<=30),"De 21 a 30",IF(AND(B23>=31,B23<=40),"De 31 a 40",IF(B23>=41,"De 41 y más","ERROR"))))))) -> 1
A4: Referencia | B4: LR5-72HTH-570M | D4: Num mod FV | H4: =IF(B20="COBRE",IF(OR(B21="90 ºC",B21="120 ºC"),INDEX('Cap 3 NTC'!P8:P37,MATCH(B32,'Cap 3 NTC'!P8:P37,-1)),IF(B21="75 ºC",INDEX('Cap 3 NTC'!O8:O37,MATCH(B32,'Cap 3 NTC'!O8:O37,-1)),INDEX('Cap 3 NTC'!N8:N37,MATCH(B32,'Cap 3 NTC'!N8:N37,-1)))),IF(OR(B21="90 ºC",B21="120 ºC"),INDEX('Cap 3 NTC'!S8:S37,MATCH(B32,'Cap 3 NTC'!S8:S37,-1)),IF(B21="75 ºC",INDEX('Cap 3 NTC'!R8:R37,MATCH(B32,'Cap 3 NTC'!R8:R37,-1)),INDEX('Cap 3 NTC'!Q8:Q37,MATCH(B32,'Cap 3 NTC'!Q8:Q37,-1))))) -> 18
A5: Potencia max [Wp] | B5: 570 | C5: =($B$5*$D$5)/1000 -> 10.83 | D5: 19
A6: Voc [V DC] | B6: 51.91 | C6: =B6*$D$5 -> 986.29
A7: Isc [A] | B7: 14.07
A8: Vmpp [V DC] | B8: 43.76 | C8: =B8*$D$5 -> 831.44
A9: Impp [A] | B9: 13.03
A11: 1. CORRIENTE MÁXIMA DEL CIRCUITO
A13: Paralelo realizado en | B13: SIN PARALELO
A14: Número de strings en paralelo | B14: 1 | C14: Paralelo hecho en Combiner Box saliendo para los MPPT1
A15: Imax [A] | B15: =B14*B7 -> 14.07
A17: 2. CÁLCULO DEL CALIBRE DEL CABLEADO
A19: Temperatura ambiente [°C] | B19: 24 | C19: Ingrese la temperatura maxima promedio del lugar de instalación
A20: Material del conductor a dimensionar | B20: COBRE
A21: Temperatura nominal del conductor [°C] | B21: 90 ºC
A22: Tipo de soporte de cables para el cálculo | B22: TUBERIA | C22: Por la Excepción del articulo 310.15 c). Cuando se obtengan dos capacidades de corriente distintas para partes seguidas de un circuito, se permite utilizar la mayor más allá del punto de transición, a la menor de las siguientes distanclas : 3,0 m o el 10 % de la longitud del circuito que da la capacidad de corriente mayor.
A23: Número de conductores portadores de corriente por la tubería | B23: 2 | C23: Ingrese SOLO el número de conductores portadores de corriente, NO incluir neutros ni tierras.
A25: Calculo de Ampacidades
A26: Ampacidad minima A1 [A] | B26: =1.25*B15 -> 17.5875 | C26: 220-10. b) y 690-8 a) NTC 2050
A28: Ft | B28: =IF(B20="COBRE",VLOOKUP(H2,'Cap 3 NTC'!A41:D50,MATCH(B21,'Cap 3 NTC'!A4:D4,0),FALSE),VLOOKUP(H2,'Cap 3 NTC'!A41:G50,MATCH(B21,'Cap 3 NTC'!E4:G4,0)+4,FALSE)) -> 1.04 | C28: Factor por temperatura ambiente | F28: 318-11 b) Los factores de corrección de la Sección 310, Nota 8.a) de las Notas a las Tablas de capacidad de corriente de 0 a 2 000 V, no se deben aplicar a la capacidad de corriente de los cables en bandejas.
A29: Fag | B29: =IF(B22="BANDEJA PORTACABLES",1,IF(AND(B23>=1,B23<=3),1,VLOOKUP(H3,'Cap 3 NTC'!J41:K46,2,FALSE))) -> 1 | C29: Factor por agrupación de conductores | F29: Ft en bandejas es 1,0 por articulo NTC 2050 318-11. b) Capacidad de corriente de los cables de 2 000 V o menos en las bandejas portacables
A30: Ampacidad 2 [A] | B30: =B15/(B28*B29) -> 13.528846 | C30: tablas 310-16 a la 310-19 NTC 2050 | G30: REVISAR SI EN BANDEJA PORTACABLES SE CONSIDERA EL CONDUCTOR AL AIRE LIBRE Y SE ESCOGERIA LA AMPACIDAD DE LA TABLA 310-15, NO DE LA 310-16
A32: AMPACIDAD MINIMA DEL CABLE [A] | B32: =IF(B30>=B26,B30,B26) -> 17.5875
A33: CALIBRE MINIMO DEL CABLE AWG | B33: =IF(B20="COBRE",IF(OR(B21="90 ºC",B21="120 ºC"),VLOOKUP(H4,'Cap 3 NTC'!P8:U37,6,FALSE),IF(B21="75 ºC",VLOOKUP(H4,'Cap 3 NTC'!O8:U37,7,FALSE),IF(B21="60 ºC",VLOOKUP(H4,'Cap 3 NTC'!N8:U37,8,FALSE)))),IF(OR(B21="90 ºC",B21="120 ºC"),VLOOKUP(H4,'Cap 3 NTC'!S8:U37,3,FALSE),IF(B21="75 ºC",VLOOKUP(H4,'Cap 3 NTC'!R8:U37,4,FALSE),IF(B21="60 ºC",VLOOKUP(H4,'Cap 3 NTC'!Q8:U37,5,FALSE))))) -> 16
A35: CALIBRE CABLE SELECCIONADO | B35: 12 AWG | C35: Seleccione un cable con calibre mayor o igual al calibre minimo del paso anterior
A36: Equivalencia en mm² | B36: =VLOOKUP(B35,Cables!F3:G28,2,FALSE) -> 4
A38: 3. SELECCIÓN DE PROTECCIÓN DEL CIRCUITO
A40: Corriente minima de dispositivo Iocpd [A] | B40: =1.25*B15 -> 17.5875 | C40: 210-22 c) y 690-8 a) de la NTC2050
A42: Corriente de corte de proteccion seleccionada [A] | B42: 20 | C42: Ingrese el valor de la corriente de corte del dispositivo de protección contra sobrecorrientes a instalar.
A44: =IF(B42>=B40,"OK","ERROR") -> OK | B44: =IF(A44="OK","Protección seleccionada es mayor a la corriente minima de OCPD",IF(A44="ERROR","La protección seleccionada debe ser mayor a la corriente minima de OCPD")) -> Protección seleccionada es mayor a la corriente minima de OCPD | F44: artículo 27.4.3 c) del RETIE
A47: 4. VALIDACION DE LA PROTECCIÓN CONTRA SOBRECORRIENTES
A49: Temperatura nominal de funcionamiento de los conectores [°C] | B49: 60 ºC | C49: Seleccione la temperatura nominal de los conectores de los equipos. Todos los puntos de conexión, cables y equipos en una instalación eléctrica deberán soportar 60°C si conducen 100A o menos, si conducen mas de 100A podrán soportar 75°C. Sección 110-14 C de la NTC2050 y el articulo 20.2.9 f) del retie
A51: =CONCATENATE("Ampacidad del cable seleccionado @", B49, " [A]") -> Ampacidad del cable seleccionado @60 ºC [A] | B51: =IF(B20="COBRE",IF(OR(B49="90 ºC",B49="120 ºC"),VLOOKUP(B35,'Cap 3 NTC'!M8:P37,4,FALSE),IF(B49="75 ºC",VLOOKUP(B35,'Cap 3 NTC'!M8:O37,3,FALSE),IF(B49="60 ºC",VLOOKUP(B35,'Cap 3 NTC'!M8:N37,2,FALSE)))),IF(OR(B49="90 ºC",B49="120 ºC"),VLOOKUP(B35,'Cap 3 NTC'!M8:S37,7,FALSE),IF(B49="75 ºC",VLOOKUP(B35,'Cap 3 NTC'!M8:R37,6,FALSE),IF(B49="60 ºC",VLOOKUP(B35,'Cap 3 NTC'!M8:Q37,5,FALSE))))) -> 25
A52: Sirve la proteccion seleccionada? | B52: =IF(B51>=B42,"SI","NO") -> SI | C52: Según articulo 110-14.c) de la NTC 20150 y articulo 20.2.9 f del RETIE
A54: =CONCATENATE("Ampacidad del cable seleccionado temperatura nominal @", B21, " [A]") -> Ampacidad del cable seleccionado temperatura nominal @90 ºC [A] | B54: =IF(B20="COBRE",IF(OR(B21="90 ºC",B21="120 ºC"),VLOOKUP(B35,'Cap 3 NTC'!M8:P37,4,FALSE),IF(B21="75 ºC",VLOOKUP(B35,'Cap 3 NTC'!M8:O37,3,FALSE),IF(B21="60 ºC",VLOOKUP(B35,'Cap 3 NTC'!M8:N37,2,FALSE)))),IF(OR(B21="90 ºC",B21="120 ºC"),VLOOKUP(B35,'Cap 3 NTC'!M8:S37,7,FALSE),IF(B21="75 ºC",VLOOKUP(B35,'Cap 3 NTC'!M8:R37,6,FALSE),IF(B21="60 ºC",VLOOKUP(B35,'Cap 3 NTC'!M8:Q37,5,FALSE))))) -> 30
A55: Corrección de Ampacidad X factores de temperatura [A] | B55: =B54*B29*B28 -> 31.2 | C55: =0.96*40 -> 38.4
A56: Sirve la proteccion seleccionada? | B56: =IF(B55>=B42,"SI","NO") -> SI
A58: =IF(AND(B56="SI",B52="SI"), "OK",IF(OR(B56="NO",B52="NO"),"ERROR")) -> OK | B58: =IF(AND(B56="SI",B52="SI"), "La protección contra sobrecorrientes seleccionada funciona correctamente con el cable seleccionado",IF(OR(B56="NO",B52="NO"),"Realice un nuevo cálculo del cableado a utilizar o de la protección contra sobrecorrientes a utilizar")) -> La protección contra sobrecorrientes seleccionada funciona correctamente con el cable seleccionado
...

Sheet PV_INV_PARALELO
A1: Información de módulos solares fotovoltaicos | H1: Casillas de control
A2: Parametro | B2: Valor | H2: =IF(AND(B19>=21,B19<=25),"21-25",IF(AND(B19>=26,B19<=30),"26-30",IF(AND(B19>=31,B19<=35),"31-35",IF(AND(B19>=36,B19<=40),"36-40",IF(AND(B19>=41,B19<=45),"41-45",IF(AND(B19>=46,B19<=50),"46-50",IF(AND(B19>=51,B19<=55),"51-55",IF(AND(B19>=56,B19<=60),"56-60",IF(AND(B19>=61,B19<=70),"61-70",IF(AND(B19>=71,B19<=80),"71-80","ERROR")))))))))) -> 21-25
A3: Fabricante | H3: =IF(AND(B23>=1,B23<=3),1,IF(AND(B23>=4,B23<=6),"De 4 a 6",IF(AND(B23>=7,B23<=9),"De 7 a 9",IF(AND(B23>=10,B23<=20),"De 10 a 20",IF(AND(B23>=21,B23<=30),"De 21 a 30",IF(AND(B23>=31,B23<=40),"De 31 a 40",IF(B23>=41,"De 41 y más","ERROR"))))))) -> De 7 a 9
A4: Referencia | D4: Num mod FV | H4: =IF(B20="COBRE",IF(OR(B21="90 ºC",B21="120 ºC"),INDEX('Cap 3 NTC'!P8:P37,MATCH(B32,'Cap 3 NTC'!P8:P37,-1)),IF(B21="75 ºC",INDEX('Cap 3 NTC'!O8:O37,MATCH(B32,'Cap 3 NTC'!O8:O37,-1)),INDEX('Cap 3 NTC'!N8:N37,MATCH(B32,'Cap 3 NTC'!N8:N37,-1)))),IF(OR(B21="90 ºC",B21="120 ºC"),INDEX('Cap 3 NTC'!S8:S37,MATCH(B32,'Cap 3 NTC'!S8:S37,-1)),IF(B21="75 ºC",INDEX('Cap 3 NTC'!R8:R37,MATCH(B32,'Cap 3 NTC'!R8:R37,-1)),INDEX('Cap 3 NTC'!Q8:Q37,MATCH(B32,'Cap 3 NTC'!Q8:Q37,-1))))) -> 14
A5: Potencia max [Wp] | C5: =B5*$D$5 -> 0 | D5: 8
A6: Voc [V DC] | C6: =B6*$D$5 -> 0
A7: Isc [A]
A8: Vmpp [V DC] | C8: =B8*$D$5 -> 0
A9: Impp [A]
A11: 1. CORRIENTE MÁXIMA DEL CIRCUITO
A13: Paralelo realizado en | B13: SIN PARALELO
A14: Número de strings en paralelo | B14: 1 | C14: Paralelo hecho en Combiner Box saliendo para los MPPT1
A15: Imax [A] | B15: =B14*B7 -> 0
A17: 2. CÁLCULO DEL CALIBRE DEL CABLEADO
A19: Temperatura ambiente [°C] | B19: 22 | C19: Ingrese la temperatura maxima promedio del lugar de instalación
A20: Material del conductor a dimensionar | B20: COBRE
A21: Temperatura nominal del conductor [°C] | B21: 90 ºC
A22: Tipo de soporte de cables para el cálculo | B22: TUBERIA | C22: Por la Excepción del articulo 310.15 c). Cuando se obtengan dos capacidades de corriente distintas para partes seguidas de un circuito, se permite utilizar la mayor más allá del punto de transición, a la menor de las siguientes distanclas : 3,0 m o el 10 % de la longitud del circuito que da la capacidad de corriente mayor.
A23: Número de conductores portadores de corriente por la tubería | B23: 8 | C23: Ingrese SOLO el número de conductores portadores de corriente, NO incluir neutros ni tierras.
A25: Calculo de Ampacidades
A26: Ampacidad minima A1 [A] | B26: =1.25*B15 -> 0 | C26: 220-10. b) y 690-8 a) NTC 2050
A28: Ft | B28: =IF(B20="COBRE",VLOOKUP(H2,'Cap 3 NTC'!A41:D50,MATCH(B21,'Cap 3 NTC'!A4:D4,0),FALSE),VLOOKUP(H2,'Cap 3 NTC'!A41:G50,MATCH(B21,'Cap 3 NTC'!E4:G4,0)+4,FALSE)) -> 1.04 | C28: Factor por temperatura ambiente | F28: 318-11 b) Los factores de corrección de la Sección 310, Nota 8.a) de las Notas a las Tablas de capacidad de corriente de 0 a 2 000 V, no se deben aplicar a la capacidad de corriente de los cables en bandejas.
A29: Fag | B29: =IF(B22="BANDEJA PORTACABLES",1,IF(AND(B23>=1,B23<=3),1,VLOOKUP(H3,'Cap 3 NTC'!J41:K46,2,FALSE))) -> 0.7 | C29: Factor por agrupación de conductores | F29: Ft en bandejas es 1,0 por articulo NTC 2050 318-11. b) Capacidad de corriente de los cables de 2 000 V o menos en las bandejas portacables
A30: Ampacidad 2 [A] | B30: =B15/(B28*B29) -> 0 | C30: tablas 310-16 a la 310-19 NTC 2050 | G30: REVISAR SI EN BANDEJA PORTACABLES SE CONSIDERA EL CONDUCTOR AL AIRE LIBRE Y SE ESCOGERIA LA AMPACIDAD DE LA TABLA 310-15, NO DE LA 310-16
A32: AMPACIDAD MINIMA DEL CABLE [A] | B32: =IF(B30>=B26,B30,B26) -> 0
A33: CALIBRE MINIMO DEL CABLE AWG | B33: =IF(B20="COBRE",IF(OR(B21="90 ºC",B21="120 ºC"),VLOOKUP(H4,'Cap 3 NTC'!P8:U37,6,FALSE),IF(B21="75 ºC",VLOOKUP(H4,'Cap 3 NTC'!O8:U37,7,FALSE),IF(B21="60 ºC",VLOOKUP(H4,'Cap 3 NTC'!N8:U37,8,FALSE)))),IF(OR(B21="90 ºC",B21="120 ºC"),VLOOKUP(H4,'Cap 3 NTC'!S8:U37,3,FALSE),IF(B21="75 ºC",VLOOKUP(H4,'Cap 3 NTC'!R8:U37,4,FALSE),IF(B21="60 ºC",VLOOKUP(H4,'Cap 3 NTC'!Q8:U37,5,FALSE))))) -> 18
A35: CALIBRE CABLE SELECCIONADO | B35: 12 AWG | C35: Seleccione un cable con calibre mayor o igual al calibre minimo del paso anterior
A36: Equivalencia en mm² | B36: =VLOOKUP(B35,Cables!F3:G28,2,FALSE) -> 4
A38: 3. SELECCIÓN DE PROTECCIÓN DEL CIRCUITO
A40: Corriente minima de dispositivo Iocpd [A] | B40: =1.25*B15 -> 0 | C40: 210-22 c) y 690-8 a) de la NTC2050
A42: Corriente de corte de proteccion seleccionada [A] | B42: 15 | C42: Ingrese el valor de la corriente de corte del dispositivo de protección contra sobrecorrientes a instalar.
A44: =IF(B42>=B40,"OK","ERROR") -> OK | B44: =IF(A44="OK","Protección seleccionada es mayor a la corriente minima de OCPD",IF(A44="ERROR","La protección seleccionada debe ser mayor a la corriente minima de OCPD")) -> Protección seleccionada es mayor a la corriente minima de OCPD | F44: artículo 27.4.3 c) del RETIE
A47: 4. VALIDACION DE LA PROTECCIÓN CONTRA SOBRECORRIENTES
A49: Temperatura nominal de funcionamiento de los conectores [°C] | B49: 60 ºC | C49: Seleccione la temperatura nominal de los conectores de los equipos. Todos los puntos de conexión, cables y equipos en una instalación eléctrica deberán soportar 60°C si conducen 100A o menos, si conducen mas de 100A podrán soportar 75°C. Sección 110-14 C de la NTC2050 y el articulo 20.2.9 f) del retie
A51: =CONCATENATE("Ampacidad del cable seleccionado @", B49, " [A]") -> Ampacidad del cable seleccionado @60 ºC [A] | B51: =IF(B20="COBRE",IF(OR(B49="90 ºC",B49="120 ºC"),VLOOKUP(B35,'Cap 3 NTC'!M8:P37,4,FALSE),IF(B49="75 ºC",VLOOKUP(B35,'Cap 3 NTC'!M8:O37,3,FALSE),IF(B49="60 ºC",VLOOKUP(B35,'Cap 3 NTC'!M8:N37,2,FALSE)))),IF(OR(B49="90 ºC",B49="120 ºC"),VLOOKUP(B35,'Cap 3 NTC'!M8:S37,7,FALSE),IF(B49="75 ºC",VLOOKUP(B35,'Cap 3 NTC'!M8:R37,6,FALSE),IF(B49="60 ºC",VLOOKUP(B35,'Cap 3 NTC'!M8:Q37,5,FALSE))))) -> 25
A52: Sirve la proteccion seleccionada? | B52: =IF(B51>=B42,"SI","NO") -> SI | C52: Según articulo 110-14.c) de la NTC 20150 y articulo 20.2.9 f del RETIE
A54: =CONCATENATE("Ampacidad del cable seleccionado temperatura nominal @", B21, " [A]") -> Ampacidad del cable seleccionado temperatura nominal @90 ºC [A] | B54: =IF(B20="COBRE",IF(OR(B21="90 ºC",B21="120 ºC"),VLOOKUP(B35,'Cap 3 NTC'!M8:P37,4,FALSE),IF(B21="75 ºC",VLOOKUP(B35,'Cap 3 NTC'!M8:O37,3,FALSE),IF(B21="60 ºC",VLOOKUP(B35,'Cap 3 NTC'!M8:N37,2,FALSE)))),IF(OR(B21="90 ºC",B21="120 ºC"),VLOOKUP(B35,'Cap 3 NTC'!M8:S37,7,FALSE),IF(B21="75 ºC",VLOOKUP(B35,'Cap 3 NTC'!M8:R37,6,FALSE),IF(B21="60 ºC",VLOOKUP(B35,'Cap 3 NTC'!M8:Q37,5,FALSE))))) -> 30
A55: Corrección de Ampacidad X factores de temperatura [A] | B55: =B54*B29*B28 -> 21.84 | C55: =0.96*40 -> 38.4
A56: Sirve la proteccion seleccionada? | B56: =IF(B55>=B42,"SI","NO") -> SI
A58: =IF(AND(B56="SI",B52="SI"), "OK",IF(OR(B56="NO",B52="NO"),"ERROR")) -> OK | B58: =IF(AND(B56="SI",B52="SI"), "La protección contra sobrecorrientes seleccionada funciona correctamente con el cable seleccionado",IF(OR(B56="NO",B52="NO"),"Realice un nuevo cálculo del cableado a utilizar o de la protección contra sobrecorrientes a utilizar")) -> La protección contra sobrecorrientes seleccionada funciona correctamente con el cable seleccionado
...

Sheet INV1_TABLERO FV
A1: Información de los inversores | H1: Casillas de control
A2: Parametro | B2: Valor | H2: =IF(AND(B16>=21,B16<=25),"21-25",IF(AND(B16>=26,B16<=30),"26-30",IF(AND(B16>=31,B16<=35),"31-35",IF(AND(B16>=36,B16<=40),"36-40",IF(AND(B16>=41,B16<=45),"41-45",IF(AND(B16>=46,B16<=50),"46-50",IF(AND(B16>=51,B16<=55),"51-55",IF(AND(B16>=56,B16<=60),"56-60",IF(AND(B16>=61,B16<=70),"61-70",IF(AND(B16>=71,B16<=80),"71-80","ERROR")))))))))) -> 21-25
A3: Fabricante | B3: Growatt | H3: =IF(AND(B20>=1,B20<=3),1,IF(AND(B20>=4,B20<=6),"De 4 a 6",IF(AND(B20>=7,B20<=9),"De 7 a 9",IF(AND(B20>=10,B20<=20),"De 10 a 20",IF(AND(B20>=21,B20<=30),"De 21 a 30",IF(AND(B20>=31,B20<=40),"De 31 a 40",IF(B20>=41,"De 41 y más","ERROR"))))))) -> 1
A4: Referencia | B4: MIN10000 TL-X2 | H4: =IF(B17="COBRE",IF(OR(B18="90 ºC",B18="120 ºC"),INDEX('Cap 3 NTC'!P8:P37,MATCH(B29,'Cap 3 NTC'!P8:P37,-1)),IF(B18="75 ºC",INDEX('Cap 3 NTC'!O8:O37,MATCH(B29,'Cap 3 NTC'!O8:O37,-1)),INDEX('Cap 3 NTC'!N8:N37,MATCH(B29,'Cap 3 NTC'!N8:N37,-1)))),IF(OR(B18="90 ºC",B18="120 ºC"),INDEX('Cap 3 NTC'!S8:S37,MATCH(B29,'Cap 3 NTC'!S8:S37,-1)),IF(B18="75 ºC",INDEX('Cap 3 NTC'!R8:R37,MATCH(B29,'Cap 3 NTC'!R8:R37,-1)),INDEX('Cap 3 NTC'!Q8:Q37,MATCH(B29,'Cap 3 NTC'!Q8:Q37,-1))))) -> 55
A5: Potencia nominal [kW] | B5: 10
A6: Voltaje de salida [V AC] | B6: 220
A7: Corriente máxima de salida [A] | B7: 45.5
A8: Número de fases | B8: 2
A10: 1. CORRIENTE MÁXIMA DEL CIRCUITO
A12: Imax [A] | B12: =B7 -> 45.5
A14: 2. CÁLCULO DEL CALIBRE DEL CABLEADO
A16: Temperatura ambiente [°C] | B16: 24 | C16: Ingrese la temperatura maxima promedio del lugar de instalación
A17: Material del conductor a dimensionar | B17: COBRE
A18: Temperatura nominal del conductor [°C] | B18: 90 ºC
A19: Tipo de soporte de cables para el cálculo | B19: TUBERIA | C19: Por la Excepción del articulo 310.15 c). Cuando se obtengan dos capacidades de corriente distintas para partes seguidas de un circuito, se permite utilizar la mayor más allá del punto de transición, a la menor de las siguientes distanclas : 3,0 m o el 10 % de la longitud del circuito que da la capacidad de corriente mayor.
A20: Número de conductores portadores de corriente por la tubería | B20: 2 | C20: La salida del inversor es trifásica
A22: Calculo de Ampacidades
A23: Ampacidad minima A1 [A] | B23: =B12 -> 45.5 | C23: 220-10. b) NTC 2050
A25: Ft | B25: =IF(B17="COBRE",VLOOKUP(H2,'Cap 3 NTC'!A41:D50,MATCH(B18,'Cap 3 NTC'!A4:D4,0),FALSE),VLOOKUP(H2,'Cap 3 NTC'!A41:G50,MATCH(B18,'Cap 3 NTC'!E4:G4,0)+4,FALSE)) -> 1.04 | C25: Factor por temperatura ambiente | F25: 318-11 b) Los factores de corrección de la Sección 310, Nota 8.a) de las Notas a las Tablas de capacidad de corriente de 0 a 2 000 V, no se deben aplicar a la capacidad de corriente de los cables en bandejas.
A26: Fag | B26: =IF(B19="BANDEJA PORTACABLES",1,IF(AND(B20>=1,B20<=3),1,VLOOKUP(H3,'Cap 3 NTC'!J41:K46,2,FALSE))) -> 1 | C26: Factor por agrupación de conductores | F26: Ft en bandejas es 1,0 por articulo NTC 2050 318-11. b) Capacidad de corriente de los cables de 2 000 V o menos en las bandejas portacables
A27: Ampacidad 2 [A] | B27: =B12/(B25*B26) -> 43.75 | C27: tablas 310-16 a la 310-19 NTC 2050 | G27: REVISAR SI EN BANDEJA PORTACABLES SE CONSIDERA EL CONDUCTOR AL AIRE LIBRE Y SE ESCOGERIA LA AMPACIDAD DE LA TABLA 310-15, NO DE LA 310-16
A29: AMPACIDAD MINIMA DEL CABLE [A] | B29: =IF(B27>=B23,B27,B23) -> 45.5
A30: CALIBRE MINIMO DEL CABLE AWG | B30: =IF(B17="COBRE",IF(OR(B18="90 ºC",B18="120 ºC"),VLOOKUP(H4,'Cap 3 NTC'!P8:U37,6,FALSE),IF(B18="75 ºC",VLOOKUP(H4,'Cap 3 NTC'!O8:U37,7,FALSE),IF(B18="60 ºC",VLOOKUP(H4,'Cap 3 NTC'!N8:U37,8,FALSE)))),IF(OR(B18="90 ºC",B18="120 ºC"),VLOOKUP(H4,'Cap 3 NTC'!S8:U37,3,FALSE),IF(B18="75 ºC",VLOOKUP(H4,'Cap 3 NTC'!R8:U37,4,FALSE),IF(B18="60 ºC",VLOOKUP(H4,'Cap 3 NTC'!Q8:U37,5,FALSE))))) -> 8
A32: CALIBRE CABLE SELECCIONADO | B32: 6 AWG | C32: Seleccione un cable con calibre mayor o igual al calibre minimo del paso anterior
A34: 3. SELECCIÓN DE PROTECCIÓN DEL CIRCUITO
A36: Corriente minima de dispositivo Iocpd [A] | B36: =B12 -> 45.5 | C36: 210-22 c) de la NTC2050
A38: Corriente de corte de proteccion seleccionada [A] | B38: 50 | C38: Ingrese el valor de la corriente de corte del dispositivo de protección contra sobrecorrientes a instalar.
A40: =IF(B38>=B36,"OK","ERROR") -> OK | B40: =IF(A40="OK","Protección seleccionada es mayor a la corriente minima de OCPD",IF(A40="ERROR","La protección seleccionada debe ser mayor a la corriente minima de OCPD")) -> Protección seleccionada es mayor a la corriente minima de OCPD | F40: artículo 27.4.3 c) del RETIE
A43: 4. VALIDACION DE LA PROTECCIÓN CONTRA SOBRECORRIENTES
A45: Temperatura nominal de funcionamiento de los conectores [°C] | B45: 60 ºC | C45: Seleccione la temperatura nominal de los conectores de los equipos. Todos los puntos de conexión, cables y equipos en una instalación eléctrica deberán soportar 60°C si conducen 100A o menos, si conducen mas de 100A podrán soportar 75°C. Sección 110-14 C de la NTC2050 y el articulo 20.2.9 f) del retie
A47: =CONCATENATE("Ampacidad del cable seleccionado @", B45, " [A]") -> Ampacidad del cable seleccionado @60 ºC [A] | B47: =IF(B17="COBRE",IF(OR(B45="90 ºC",B45="120 ºC"),VLOOKUP(B32,'Cap 3 NTC'!M8:P37,4,FALSE),IF(B45="75 ºC",VLOOKUP(B32,'Cap 3 NTC'!M8:O37,3,FALSE),IF(B45="60 ºC",VLOOKUP(B32,'Cap 3 NTC'!M8:N37,2,FALSE)))),IF(OR(B45="90 ºC",B45="120 ºC"),VLOOKUP(B32,'Cap 3 NTC'!M8:S37,7,FALSE),IF(B45="75 ºC",VLOOKUP(B32,'Cap 3 NTC'!M8:R37,6,FALSE),IF(B45="60 ºC",VLOOKUP(B32,'Cap 3 NTC'!M8:Q37,5,FALSE))))) -> 55
A48: Sirve la proteccion seleccionada? | B48: =IF(B47>=B38,"SI","NO") -> SI | C48: Según articulo 110-14.c) de la NTC 20150 y articulo 20.2.9 f del RETIE
A50: =CONCATENATE("Ampacidad del cable seleccionado temperatura nominal @", B18, " [A]") -> Ampacidad del cable seleccionado temperatura nominal @90 ºC [A] | B50: =IF(B17="COBRE",IF(OR(B18="90 ºC",B18="120 ºC"),VLOOKUP(B32,'Cap 3 NTC'!M8:P37,4,FALSE),IF(B18="75 ºC",VLOOKUP(B32,'Cap 3 NTC'!M8:O37,3,FALSE),IF(B18="60 ºC",VLOOKUP(B32,'Cap 3 NTC'!M8:N37,2,FALSE)))),IF(OR(B18="90 ºC",B18="120 ºC"),VLOOKUP(B32,'Cap 3 NTC'!M8:S37,7,FALSE),IF(B18="75 ºC",VLOOKUP(B32,'Cap 3 NTC'!M8:R37,6,FALSE),IF(B18="60 ºC",VLOOKUP(B32,'Cap 3 NTC'!M8:Q37,5,FALSE))))) -> 75
A51: Corrección de Ampacidad X factores de temperatura [A] | B51: =B50*B26*B25 -> 78
A52: Sirve la proteccion seleccionada? | B52: =IF(B51>=B38,"SI","NO") -> SI
A54: =IF(AND(B52="SI",B48="SI"), "OK",IF(OR(B52="NO",B48="NO"),"ERROR")) -> OK | B54: =IF(AND(B52="SI",B48="SI"), "La protección contra sobrecorrientes seleccionada funciona correctamente con el cable seleccionado",IF(OR(B52="NO",B48="NO"),"Realice un nuevo cálculo del cableado a utilizar o de la protección contra sobrecorrientes a utilizar")) -> La protección contra sobrecorrientes seleccionada funciona correctamente con el cable seleccionado
A57: 5. CÁLCULO DEL CABLE DE PUESTA A TIERRA
A59: Material del cable de puesta a tierra | B59: COBRE
A60: Calibre minimo del cable de tierra [AWG] | B60: =VLOOKUP(INDEX('Cap 2 NTC'!A36:A47,MATCH(B38,'Cap 2 NTC'!A36:A47,-1)),'Cap 2 NTC'!A36:C47,MATCH('INV1_TABLERO FV'!B59,'Cap 2 NTC'!B34:C34,0)+1,FALSE) -> 10 | C60: Articulo 250-95 de la NTC 2050 y Articulo 15 Retie
A62: Calibre de cable depuesta a tierra seleccionado | B62: 10 AWG | C62: Seleccione un cable con calibre mayor o igual al calibre minimo del paso anterior
...

Sheet INV1_TABLERO FV_N
A1: Información de los inversores | H1: Casillas de control
A2: Parametro | B2: Valor | H2: =IF(AND(B16>=21,B16<=25),"21-25",IF(AND(B16>=26,B16<=30),"26-30",IF(AND(B16>=31,B16<=35),"31-35",IF(AND(B16>=36,B16<=40),"36-40",IF(AND(B16>=41,B16<=45),"41-45",IF(AND(B16>=46,B16<=50),"46-50",IF(AND(B16>=51,B16<=55),"51-55",IF(AND(B16>=56,B16<=60),"56-60",IF(AND(B16>=61,B16<=70),"61-70",IF(AND(B16>=71,B16<=80),"71-80","ERROR")))))))))) -> 31-35
A3: Fabricante | B3: Growatt | H3: =IF(AND(B20>=1,B20<=3),1,IF(AND(B20>=4,B20<=6),"De 4 a 6",IF(AND(B20>=7,B20<=9),"De 7 a 9",IF(AND(B20>=10,B20<=20),"De 10 a 20",IF(AND(B20>=21,B20<=30),"De 21 a 30",IF(AND(B20>=31,B20<=40),"De 31 a 40",IF(B20>=41,"De 41 y más","ERROR"))))))) -> 1
A4: Referencia | B4: MAC 36KTL3-XL | H4: =IF(B17="COBRE",IF(OR(B18="90 ºC",B18="120 ºC"),INDEX('Cap 3 NTC'!P8:P37,MATCH(B29,'Cap 3 NTC'!P8:P37,-1)),IF(B18="75 ºC",INDEX('Cap 3 NTC'!O8:O37,MATCH(B29,'Cap 3 NTC'!O8:O37,-1)),INDEX('Cap 3 NTC'!N8:N37,MATCH(B29,'Cap 3 NTC'!N8:N37,-1)))),IF(OR(B18="90 ºC",B18="120 ºC"),INDEX('Cap 3 NTC'!S8:S37,MATCH(B29,'Cap 3 NTC'!S8:S37,-1)),IF(B18="75 ºC",INDEX('Cap 3 NTC'!R8:R37,MATCH(B29,'Cap 3 NTC'!R8:R37,-1)),INDEX('Cap 3 NTC'!Q8:Q37,MATCH(B29,'Cap 3 NTC'!Q8:Q37,-1))))) -> 95
A5: Potencia nominal [kW] | B5: 36
A6: Voltaje de salida [V AC] | B6: 208
A7: Corriente máxima de salida [A] | B7: 94.5
A8: Número de fases | B8: 3
A10: 1. CORRIENTE MÁXIMA DEL CIRCUITO
A12: Imax [A] | B12: =B7*70% -> 66.15
A14: 2. CÁLCULO DEL CALIBRE DEL CABLEADO
A16: Temperatura ambiente [°C] | B16: 32 | C16: Ingrese la temperatura maxima promedio del lugar de instalación
A17: Material del conductor a dimensionar | B17: COBRE
A18: Temperatura nominal del conductor [°C] | B18: 90 ºC
A19: Tipo de soporte de cables para el cálculo | B19: TUBERIA | C19: Por la Excepción del articulo 310.15 c). Cuando se obtengan dos capacidades de corriente distintas para partes seguidas de un circuito, se permite utilizar la mayor más allá del punto de transición, a la menor de las siguientes distanclas : 3,0 m o el 10 % de la longitud del circuito que da la capacidad de corriente mayor.
A20: Número de conductores portadores de corriente por la tubería | B20: 3 | C20: La salida del inversor es trifásica
A22: Calculo de Ampacidades
A23: Ampacidad minima A1 [A] | B23: =1.25*B12 -> 82.6875 | C23: 220-10. b) NTC 2050
A25: Ft | B25: =IF(B17="COBRE",VLOOKUP(H2,'Cap 3 NTC'!A41:D50,MATCH(B18,'Cap 3 NTC'!A4:D4,0),FALSE),VLOOKUP(H2,'Cap 3 NTC'!A41:G50,MATCH(B18,'Cap 3 NTC'!E4:G4,0)+4,FALSE)) -> 0.96 | C25: Factor por temperatura ambiente | F25: 318-11 b) Los factores de corrección de la Sección 310, Nota 8.a) de las Notas a las Tablas de capacidad de corriente de 0 a 2 000 V, no se deben aplicar a la capacidad de corriente de los cables en bandejas.
A26: Fag | B26: =IF(B19="BANDEJA PORTACABLES",1,IF(AND(B20>=1,B20<=3),1,VLOOKUP(H3,'Cap 3 NTC'!J41:K46,2,FALSE))) -> 1 | C26: Factor por agrupación de conductores | F26: Ft en bandejas es 1,0 por articulo NTC 2050 318-11. b) Capacidad de corriente de los cables de 2 000 V o menos en las bandejas portacables
A27: Ampacidad 2 [A] | B27: =B12/(B25*B26) -> 68.90625 | C27: tablas 310-16 a la 310-19 NTC 2050 | G27: REVISAR SI EN BANDEJA PORTACABLES SE CONSIDERA EL CONDUCTOR AL AIRE LIBRE Y SE ESCOGERIA LA AMPACIDAD DE LA TABLA 310-15, NO DE LA 310-16
A29: AMPACIDAD MINIMA DEL CABLE [A] | B29: =IF(B27>=B23,B27,B23) -> 82.6875
A30: CALIBRE MINIMO DEL CABLE AWG | B30: =IF(B17="COBRE",IF(OR(B18="90 ºC",B18="120 ºC"),VLOOKUP(H4,'Cap 3 NTC'!P8:U37,6,FALSE),IF(B18="75 ºC",VLOOKUP(H4,'Cap 3 NTC'!O8:U37,7,FALSE),IF(B18="60 ºC",VLOOKUP(H4,'Cap 3 NTC'!N8:U37,8,FALSE)))),IF(OR(B18="90 ºC",B18="120 ºC"),VLOOKUP(H4,'Cap 3 NTC'!S8:U37,3,FALSE),IF(B18="75 ºC",VLOOKUP(H4,'Cap 3 NTC'!R8:U37,4,FALSE),IF(B18="60 ºC",VLOOKUP(H4,'Cap 3 NTC'!Q8:U37,5,FALSE))))) -> 4
A32: CALIBRE CABLE SELECCIONADO | B32: 4 AWG | C32: Seleccione un cable con calibre mayor o igual al calibre minimo del paso anterior
A34: 3. SELECCIÓN DE PROTECCIÓN DEL CIRCUITO
A36: Corriente minima de dispositivo Iocpd [A] | B36: =1.25*B12 -> 82.6875 | C36: 210-22 c) de la NTC2050
A38: Corriente de corte de proteccion seleccionada [A] | B38: 125 | C38: Ingrese el valor de la corriente de corte del dispositivo de protección contra sobrecorrientes a instalar.
A40: =IF(B38>=B36,"OK","ERROR") -> OK | B40: =IF(A40="OK","Protección seleccionada es mayor a la corriente minima de OCPD",IF(A40="ERROR","La protección seleccionada debe ser mayor a la corriente minima de OCPD")) -> Protección seleccionada es mayor a la corriente minima de OCPD | F40: artículo 27.4.3 c) del RETIE
A43: 4. VALIDACION DE LA PROTECCIÓN CONTRA SOBRECORRIENTES
A45: Temperatura nominal de funcionamiento de los conectores [°C] | B45: 75 ºC | C45: Seleccione la temperatura nominal de los conectores de los equipos. Todos los puntos de conexión, cables y equipos en una instalación eléctrica deberán soportar 60°C si conducen 100A o menos, si conducen mas de 100A podrán soportar 75°C. Sección 110-14 C de la NTC2050 y el articulo 20.2.9 f) del retie
A47: =CONCATENATE("Ampacidad del cable seleccionado @", B45, " [A]") -> Ampacidad del cable seleccionado @75 ºC [A] | B47: =IF(B17="COBRE",IF(OR(B45="90 ºC",B45="120 ºC"),VLOOKUP(B32,'Cap 3 NTC'!M8:P37,4,FALSE),IF(B45="75 ºC",VLOOKUP(B32,'Cap 3 NTC'!M8:O37,3,FALSE),IF(B45="60 ºC",VLOOKUP(B32,'Cap 3 NTC'!M8:N37,2,FALSE)))),IF(OR(B45="90 ºC",B45="120 ºC"),VLOOKUP(B32,'Cap 3 NTC'!M8:S37,7,FALSE),IF(B45="75 ºC",VLOOKUP(B32,'Cap 3 NTC'!M8:R37,6,FALSE),IF(B45="60 ºC",VLOOKUP(B32,'Cap 3 NTC'!M8:Q37,5,FALSE))))) -> 85
A48: Sirve la proteccion seleccionada? | B48: =IF(B47>=B38,"SI","NO") -> NO | C48: Según articulo 110-14.c) de la NTC 20150 y articulo 20.2.9 f del RETIE
A50: =CONCATENATE("Ampacidad del cable seleccionado temperatura nominal @", B18, " [A]") -> Ampacidad del cable seleccionado temperatura nominal @90 ºC [A] | B50: =IF(B17="COBRE",IF(OR(B18="90 ºC",B18="120 ºC"),VLOOKUP(B32,'Cap 3 NTC'!M8:P37,4,FALSE),IF(B18="75 ºC",VLOOKUP(B32,'Cap 3 NTC'!M8:O37,3,FALSE),IF(B18="60 ºC",VLOOKUP(B32,'Cap 3 NTC'!M8:N37,2,FALSE)))),IF(OR(B18="90 ºC",B18="120 ºC"),VLOOKUP(B32,'Cap 3 NTC'!M8:S37,7,FALSE),IF(B18="75 ºC",VLOOKUP(B32,'Cap 3 NTC'!M8:R37,6,FALSE),IF(B18="60 ºC",VLOOKUP(B32,'Cap 3 NTC'!M8:Q37,5,FALSE))))) -> 95
A51: Corrección de Ampacidad X factores de temperatura [A] | B51: =B50*B26*B25 -> 91.2
A52: Sirve la proteccion seleccionada? | B52: =IF(B51>=B38,"SI","NO") -> NO
A54: =IF(AND(B52="SI",B48="SI"), "OK",IF(OR(B52="NO",B48="NO"),"ERROR")) -> ERROR | B54: =IF(AND(B52="SI",B48="SI"), "La protección contra sobrecorrientes seleccionada funciona correctamente con el cable seleccionado",IF(OR(B52="NO",B48="NO"),"Realice un nuevo cálculo del cableado a utilizar o de la protección contra sobrecorrientes a utilizar")) -> Realice un nuevo cálculo del cableado a utilizar o de la protección contra sobrecorrientes a utilizar
A57: 5. CÁLCULO DEL CABLE DE PUESTA A TIERRA
A59: Material del cable de puesta a tierra | B59: COBRE
A60: Calibre minimo del cable de tierra [AWG] | B60: =VLOOKUP(INDEX('Cap 2 NTC'!A36:A47,MATCH(B38,'Cap 2 NTC'!A36:A47,-1)),'Cap 2 NTC'!A36:C47,MATCH('INV1_TABLERO FV_N'!B59,'Cap 2 NTC'!B34:C34,0)+1,FALSE) -> 6 | C60: Articulo 250-95 de la NTC 2050 y Articulo 15 Retie
A62: Calibre de cable depuesta a tierra seleccionado | B62: 6 AWG | C62: Seleccione un cable con calibre mayor o igual al calibre minimo del paso anterior
...

Sheet INV2_TABLERO FV
A1: Información de los inversores | H1: Casillas de control
A2: Parametro | B2: Valor | H2: =IF(AND(B16>=21,B16<=25),"21-25",IF(AND(B16>=26,B16<=30),"26-30",IF(AND(B16>=31,B16<=35),"31-35",IF(AND(B16>=36,B16<=40),"36-40",IF(AND(B16>=41,B16<=45),"41-45",IF(AND(B16>=46,B16<=50),"46-50",IF(AND(B16>=51,B16<=55),"51-55",IF(AND(B16>=56,B16<=60),"56-60",IF(AND(B16>=61,B16<=70),"61-70",IF(AND(B16>=71,B16<=80),"71-80","ERROR")))))))))) -> 31-35
A3: Fabricante | B3: Growatt | H3: =IF(AND(B20>=1,B20<=3),1,IF(AND(B20>=4,B20<=6),"De 4 a 6",IF(AND(B20>=7,B20<=9),"De 7 a 9",IF(AND(B20>=10,B20<=20),"De 10 a 20",IF(AND(B20>=21,B20<=30),"De 21 a 30",IF(AND(B20>=31,B20<=40),"De 31 a 40",IF(B20>=41,"De 41 y más","ERROR"))))))) -> 1
A4: Referencia | B4: MAC 30KTL3-XL | H4: =IF(B17="COBRE",IF(OR(B18="90 ºC",B18="120 ºC"),INDEX('Cap 3 NTC'!P8:P37,MATCH(B29,'Cap 3 NTC'!P8:P37,-1)),IF(B18="75 ºC",INDEX('Cap 3 NTC'!O8:O37,MATCH(B29,'Cap 3 NTC'!O8:O37,-1)),INDEX('Cap 3 NTC'!N8:N37,MATCH(B29,'Cap 3 NTC'!N8:N37,-1)))),IF(OR(B18="90 ºC",B18="120 ºC"),INDEX('Cap 3 NTC'!S8:S37,MATCH(B29,'Cap 3 NTC'!S8:S37,-1)),IF(B18="75 ºC",INDEX('Cap 3 NTC'!R8:R37,MATCH(B29,'Cap 3 NTC'!R8:R37,-1)),INDEX('Cap 3 NTC'!Q8:Q37,MATCH(B29,'Cap 3 NTC'!Q8:Q37,-1))))) -> 110
A5: Potencia nominal [kW] | B5: 30
A6: Voltaje de salida [V AC] | B6: 208
A7: Corriente máxima de salida [A] | B7: 87.4
A8: Número de fases | B8: 3
A10: 1. CORRIENTE MÁXIMA DEL CIRCUITO
A12: Imax [A] | B12: =B7 -> 87.4
A14: 2. CÁLCULO DEL CALIBRE DEL CABLEADO
A16: Temperatura ambiente [°C] | B16: 32 | C16: Ingrese la temperatura maxima promedio del lugar de instalación
A17: Material del conductor a dimensionar | B17: COBRE
A18: Temperatura nominal del conductor [°C] | B18: 90 ºC
A19: Tipo de soporte de cables para el cálculo | B19: BANDEJA PORTACABLES | C19: Por la Excepción del articulo 310.15 c). Cuando se obtengan dos capacidades de corriente distintas para partes seguidas de un circuito, se permite utilizar la mayor más allá del punto de transición, a la menor de las siguientes distanclas : 3,0 m o el 10 % de la longitud del circuito que da la capacidad de corriente mayor.
A20: Número de conductores portadores de corriente por la tubería | B20: 3 | C20: La salida del inversor es trifásica
A22: Calculo de Ampacidades
A23: Ampacidad minima A1 [A] | B23: =1.25*B12 -> 109.25 | C23: 220-10. b) NTC 2050
A25: Ft | B25: =IF(B17="COBRE",VLOOKUP(H2,'Cap 3 NTC'!A41:D50,MATCH(B18,'Cap 3 NTC'!A4:D4,0),FALSE),VLOOKUP(H2,'Cap 3 NTC'!A41:G50,MATCH(B18,'Cap 3 NTC'!E4:G4,0)+4,FALSE)) -> 0.96 | C25: Factor por temperatura ambiente | F25: 318-11 b) Los factores de corrección de la Sección 310, Nota 8.a) de las Notas a las Tablas de capacidad de corriente de 0 a 2 000 V, no se deben aplicar a la capacidad de corriente de los cables en bandejas.
A26: Fag | B26: =IF(B19="BANDEJA PORTACABLES",1,IF(AND(B20>=1,B20<=3),1,VLOOKUP(H3,'Cap 3 NTC'!J41:K46,2,FALSE))) -> 1 | C26: Factor por agrupación de conductores | F26: Ft en bandejas es 1,0 por articulo NTC 2050 318-11. b) Capacidad de corriente de los cables de 2 000 V o menos en las bandejas portacables
A27: Ampacidad 2 [A] | B27: =B12/(B25*B26) -> 91.041667 | C27: tablas 310-16 a la 310-19 NTC 2050 | G27: REVISAR SI EN BANDEJA PORTACABLES SE CONSIDERA EL CONDUCTOR AL AIRE LIBRE Y SE ESCOGERIA LA AMPACIDAD DE LA TABLA 310-15, NO DE LA 310-16
A29: AMPACIDAD MINIMA DEL CABLE [A] | B29: =IF(B27>=B23,B27,B23) -> 109.25
A30: CALIBRE MINIMO DEL CABLE AWG | B30: =IF(B17="COBRE",IF(OR(B18="90 ºC",B18="120 ºC"),VLOOKUP(H4,'Cap 3 NTC'!P8:U37,6,FALSE),IF(B18="75 ºC",VLOOKUP(H4,'Cap 3 NTC'!O8:U37,7,FALSE),IF(B18="60 ºC",VLOOKUP(H4,'Cap 3 NTC'!N8:U37,8,FALSE)))),IF(OR(B18="90 ºC",B18="120 ºC"),VLOOKUP(H4,'Cap 3 NTC'!S8:U37,3,FALSE),IF(B18="75 ºC",VLOOKUP(H4,'Cap 3 NTC'!R8:U37,4,FALSE),IF(B18="60 ºC",VLOOKUP(H4,'Cap 3 NTC'!Q8:U37,5,FALSE))))) -> 3
A32: CALIBRE CABLE SELECCIONADO | B32: 2 AWG | C32: Seleccione un cable con calibre mayor o igual al calibre minimo del paso anterior
A34: 3. SELECCIÓN DE PROTECCIÓN DEL CIRCUITO
A36: Corriente minima de dispositivo Iocpd [A] | B36: =1.25*B12 -> 109.25 | C36: 210-22 c) de la NTC2050
A38: Corriente de corte de proteccion seleccionada [A] | B38: 100 | C38: Ingrese el valor de la corriente de corte del dispositivo de protección contra sobrecorrientes a instalar.
A40: =IF(B38>=B36,"OK","ERROR") -> ERROR | B40: =IF(A40="OK","Protección seleccionada es mayor a la corriente minima de OCPD",IF(A40="ERROR","La protección seleccionada debe ser mayor a la corriente minima de OCPD")) -> La protección seleccionada debe ser mayor a la corriente minima de OCPD | F40: artículo 27.4.3 c) del RETIE
A43: 4. VALIDACION DE LA PROTECCIÓN CONTRA SOBRECORRIENTES
A45: Temperatura nominal de funcionamiento de los conectores [°C] | B45: 75 ºC | C45: Seleccione la temperatura nominal de los conectores de los equipos. Todos los puntos de conexión, cables y equipos en una instalación eléctrica deberán soportar 60°C si conducen 100A o menos, si conducen mas de 100A podrán soportar 75°C. Sección 110-14 C de la NTC2050 y el articulo 20.2.9 f) del retie
A47: =CONCATENATE("Ampacidad del cable seleccionado @", B45, " [A]") -> Ampacidad del cable seleccionado @75 ºC [A] | B47: =IF(B17="COBRE",IF(OR(B45="90 ºC",B45="120 ºC"),VLOOKUP(B32,'Cap 3 NTC'!M8:P37,4,FALSE),IF(B45="75 ºC",VLOOKUP(B32,'Cap 3 NTC'!M8:O37,3,FALSE),IF(B45="60 ºC",VLOOKUP(B32,'Cap 3 NTC'!M8:N37,2,FALSE)))),IF(OR(B45="90 ºC",B45="120 ºC"),VLOOKUP(B32,'Cap 3 NTC'!M8:S37,7,FALSE),IF(B45="75 ºC",VLOOKUP(B32,'Cap 3 NTC'!M8:R37,6,FALSE),IF(B45="60 ºC",VLOOKUP(B32,'Cap 3 NTC'!M8:Q37,5,FALSE))))) -> 115
A48: Sirve la proteccion seleccionada? | B48: =IF(B47>=B38,"SI","NO") -> SI | C48: Según articulo 110-14.c) de la NTC 20150 y articulo 20.2.9 f del RETIE
A50: =CONCATENATE("Ampacidad del cable seleccionado temperatura nominal @", B18, " [A]") -> Ampacidad del cable seleccionado temperatura nominal @90 ºC [A] | B50: =IF(B17="COBRE",IF(OR(B18="90 ºC",B18="120 ºC"),VLOOKUP(B32,'Cap 3 NTC'!M8:P37,4,FALSE),IF(B18="75 ºC",VLOOKUP(B32,'Cap 3 NTC'!M8:O37,3,FALSE),IF(B18="60 ºC",VLOOKUP(B32,'Cap 3 NTC'!M8:N37,2,FALSE)))),IF(OR(B18="90 ºC",B18="120 ºC"),VLOOKUP(B32,'Cap 3 NTC'!M8:S37,7,FALSE),IF(B18="75 ºC",VLOOKUP(B32,'Cap 3 NTC'!M8:R37,6,FALSE),IF(B18="60 ºC",VLOOKUP(B32,'Cap 3 NTC'!M8:Q37,5,FALSE))))) -> 130 | D50: =260*60% -> 156
A51: Corrección de Ampacidad X factores de temperatura [A] | B51: =B50*B26*B25 -> 124.8
A52: Sirve la proteccion seleccionada? | B52: =IF(B51>=B38,"SI","NO") -> SI
A54: =IF(AND(B52="SI",B48="SI"), "OK",IF(OR(B52="NO",B48="NO"),"ERROR")) -> OK | B54: =IF(AND(B52="SI",B48="SI"), "La protección contra sobrecorrientes seleccionada funciona correctamente con el cable seleccionado",IF(OR(B52="NO",B48="NO"),"Realice un nuevo cálculo del cableado a utilizar o de la protección contra sobrecorrientes a utilizar")) -> La protección contra sobrecorrientes seleccionada funciona correctamente con el cable seleccionado
A57: 5. CÁLCULO DEL CABLE DE PUESTA A TIERRA
A59: Material del cable de puesta a tierra | B59: COBRE
A60: Calibre minimo del cable de tierra [AWG] | B60: =VLOOKUP(INDEX('Cap 2 NTC'!A36:A47,MATCH(B38,'Cap 2 NTC'!A36:A47,-1)),'Cap 2 NTC'!A36:C47,MATCH('INV2_TABLERO FV'!B59,'Cap 2 NTC'!B34:C34,0)+1,FALSE) -> 8 | C60: Articulo 250-95 de la NTC 2050 y Articulo 15 Retie
A62: Calibre de cable depuesta a tierra seleccionado | B62: 8 AWG | C62: Seleccione un cable con calibre mayor o igual al calibre minimo del paso anterior
...

Sheet INV2_TABLERO FV_N
A1: Información de los inversores | H1: Casillas de control
A2: Parametro | B2: Valor | H2: =IF(AND(B16>=21,B16<=25),"21-25",IF(AND(B16>=26,B16<=30),"26-30",IF(AND(B16>=31,B16<=35),"31-35",IF(AND(B16>=36,B16<=40),"36-40",IF(AND(B16>=41,B16<=45),"41-45",IF(AND(B16>=46,B16<=50),"46-50",IF(AND(B16>=51,B16<=55),"51-55",IF(AND(B16>=56,B16<=60),"56-60",IF(AND(B16>=61,B16<=70),"61-70",IF(AND(B16>=71,B16<=80),"71-80","ERROR")))))))))) -> 31-35
A3: Fabricante | B3: Growatt | H3: =IF(AND(B20>=1,B20<=3),1,IF(AND(B20>=4,B20<=6),"De 4 a 6",IF(AND(B20>=7,B20<=9),"De 7 a 9",IF(AND(B20>=10,B20<=20),"De 10 a 20",IF(AND(B20>=21,B20<=30),"De 21 a 30",IF(AND(B20>=31,B20<=40),"De 31 a 40",IF(B20>=41,"De 41 y más","ERROR"))))))) -> 1
A4: Referencia | B4: MAC 30KTL3-XL | H4: =IF(B17="COBRE",IF(OR(B18="90 ºC",B18="120 ºC"),INDEX('Cap 3 NTC'!P8:P37,MATCH(B29,'Cap 3 NTC'!P8:P37,-1)),IF(B18="75 ºC",INDEX('Cap 3 NTC'!O8:O37,MATCH(B29,'Cap 3 NTC'!O8:O37,-1)),INDEX('Cap 3 NTC'!N8:N37,MATCH(B29,'Cap 3 NTC'!N8:N37,-1)))),IF(OR(B18="90 ºC",B18="120 ºC"),INDEX('Cap 3 NTC'!S8:S37,MATCH(B29,'Cap 3 NTC'!S8:S37,-1)),IF(B18="75 ºC",INDEX('Cap 3 NTC'!R8:R37,MATCH(B29,'Cap 3 NTC'!R8:R37,-1)),INDEX('Cap 3 NTC'!Q8:Q37,MATCH(B29,'Cap 3 NTC'!Q8:Q37,-1))))) -> 95
A5: Potencia nominal [kW] | B5: 30
A6: Voltaje de salida [V AC] | B6: 208
A7: Corriente máxima de salida [A] | B7: 87.4
A8: Número de fases | B8: 3
A10: 1. CORRIENTE MÁXIMA DEL CIRCUITO
A12: Imax [A] | B12: =B7*70% -> 61.18
A14: 2. CÁLCULO DEL CALIBRE DEL CABLEADO
A16: Temperatura ambiente [°C] | B16: 32 | C16: Ingrese la temperatura maxima promedio del lugar de instalación
A17: Material del conductor a dimensionar | B17: COBRE
A18: Temperatura nominal del conductor [°C] | B18: 90 ºC
A19: Tipo de soporte de cables para el cálculo | B19: BANDEJA PORTACABLES | C19: Por la Excepción del articulo 310.15 c). Cuando se obtengan dos capacidades de corriente distintas para partes seguidas de un circuito, se permite utilizar la mayor más allá del punto de transición, a la menor de las siguientes distanclas : 3,0 m o el 10 % de la longitud del circuito que da la capacidad de corriente mayor.
A20: Número de conductores portadores de corriente por la tubería | B20: 3 | C20: La salida del inversor es trifásica
A22: Calculo de Ampacidades
A23: Ampacidad minima A1 [A] | B23: =1.25*B12 -> 76.475 | C23: 220-10. b) NTC 2050
A25: Ft | B25: =IF(B17="COBRE",VLOOKUP(H2,'Cap 3 NTC'!A41:D50,MATCH(B18,'Cap 3 NTC'!A4:D4,0),FALSE),VLOOKUP(H2,'Cap 3 NTC'!A41:G50,MATCH(B18,'Cap 3 NTC'!E4:G4,0)+4,FALSE)) -> 0.96 | C25: Factor por temperatura ambiente | F25: 318-11 b) Los factores de corrección de la Sección 310, Nota 8.a) de las Notas a las Tablas de capacidad de corriente de 0 a 2 000 V, no se deben aplicar a la capacidad de corriente de los cables en bandejas.
A26: Fag | B26: =IF(B19="BANDEJA PORTACABLES",1,IF(AND(B20>=1,B20<=3),1,VLOOKUP(H3,'Cap 3 NTC'!J41:K46,2,FALSE))) -> 1 | C26: Factor por agrupación de conductores | F26: Ft en bandejas es 1,0 por articulo NTC 2050 318-11. b) Capacidad de corriente de los cables de 2 000 V o menos en las bandejas portacables
A27: Ampacidad 2 [A] | B27: =B12/(B25*B26) -> 63.729167 | C27: tablas 310-16 a la 310-19 NTC 2050 | G27: REVISAR SI EN BANDEJA PORTACABLES SE CONSIDERA EL CONDUCTOR AL AIRE LIBRE Y SE ESCOGERIA LA AMPACIDAD DE LA TABLA 310-15, NO DE LA 310-16
A29: AMPACIDAD MINIMA DEL CABLE [A] | B29: =IF(B27>=B23,B27,B23) -> 76.475
A30: CALIBRE MINIMO DEL CABLE AWG | B30: =IF(B17="COBRE",IF(OR(B18="90 ºC",B18="120 ºC"),VLOOKUP(H4,'Cap 3 NTC'!P8:U37,6,FALSE),IF(B18="75 ºC",VLOOKUP(H4,'Cap 3 NTC'!O8:U37,7,FALSE),IF(B18="60 ºC",VLOOKUP(H4,'Cap 3 NTC'!N8:U37,8,FALSE)))),IF(OR(B18="90 ºC",B18="120 ºC"),VLOOKUP(H4,'Cap 3 NTC'!S8:U37,3,FALSE),IF(B18="75 ºC",VLOOKUP(H4,'Cap 3 NTC'!R8:U37,4,FALSE),IF(B18="60 ºC",VLOOKUP(H4,'Cap 3 NTC'!Q8:U37,5,FALSE))))) -> 4
A32: CALIBRE CABLE SELECCIONADO | B32: 4 AWG | C32: Seleccione un cable con calibre mayor o igual al calibre minimo del paso anterior
A34: 3. SELECCIÓN DE PROTECCIÓN DEL CIRCUITO
A36: Corriente minima de dispositivo Iocpd [A] | B36: =1.25*B12 -> 76.475 | C36: 210-22 c) de la NTC2050
A38: Corriente de corte de proteccion seleccionada [A] | B38: 100 | C38: Ingrese el valor de la corriente de corte del dispositivo de protección contra sobrecorrientes a instalar.
A40: =IF(B38>=B36,"OK","ERROR") -> OK | B40: =IF(A40="OK","Protección seleccionada es mayor a la corriente minima de OCPD",IF(A40="ERROR","La protección seleccionada debe ser mayor a la corriente minima de OCPD")) -> Protección seleccionada es mayor a la corriente minima de OCPD | F40: artículo 27.4.3 c) del RETIE
A43: 4. VALIDACION DE LA PROTECCIÓN CONTRA SOBRECORRIENTES
A45: Temperatura nominal de funcionamiento de los conectores [°C] | B45: 75 ºC | C45: Seleccione la temperatura nominal de los conectores de los equipos. Todos los puntos de conexión, cables y equipos en una instalación eléctrica deberán soportar 60°C si conducen 100A o menos, si conducen mas de 100A podrán soportar 75°C. Sección 110-14 C de la NTC2050 y el articulo 20.2.9 f) del retie
A47: =CONCATENATE("Ampacidad del cable seleccionado @", B45, " [A]") -> Ampacidad del cable seleccionado @75 ºC [A] | B47: =IF(B17="COBRE",IF(OR(B45="90 ºC",B45="120 ºC"),VLOOKUP(B32,'Cap 3 NTC'!M8:P37,4,FALSE),IF(B45="75 ºC",VLOOKUP(B32,'Cap 3 NTC'!M8:O37,3,FALSE),IF(B45="60 ºC",VLOOKUP(B32,'Cap 3 NTC'!M8:N37,2,FALSE)))),IF(OR(B45="90 ºC",B45="120 ºC"),VLOOKUP(B32,'Cap 3 NTC'!M8:S37,7,FALSE),IF(B45="75 ºC",VLOOKUP(B32,'Cap 3 NTC'!M8:R37,6,FALSE),IF(B45="60 ºC",VLOOKUP(B32,'Cap 3 NTC'!M8:Q37,5,FALSE))))) -> 85
A48: Sirve la proteccion seleccionada? | B48: =IF(B47>=B38,"SI","NO") -> NO | C48: Según articulo 110-14.c) de la NTC 20150 y articulo 20.2.9 f del RETIE
A50: =CONCATENATE("Ampacidad del cable seleccionado temperatura nominal @", B18, " [A]") -> Ampacidad del cable seleccionado temperatura nominal @90 ºC [A] | B50: =IF(B17="COBRE",IF(OR(B18="90 ºC",B18="120 ºC"),VLOOKUP(B32,'Cap 3 NTC'!M8:P37,4,FALSE),IF(B18="75 ºC",VLOOKUP(B32,'Cap 3 NTC'!M8:O37,3,FALSE),IF(B18="60 ºC",VLOOKUP(B32,'Cap 3 NTC'!M8:N37,2,FALSE)))),IF(OR(B18="90 ºC",B18="120 ºC"),VLOOKUP(B32,'Cap 3 NTC'!M8:S37,7,FALSE),IF(B18="75 ºC",VLOOKUP(B32,'Cap 3 NTC'!M8:R37,6,FALSE),IF(B18="60 ºC",VLOOKUP(B32,'Cap 3 NTC'!M8:Q37,5,FALSE))))) -> 95 | D50: =260*60% -> 156
A51: Corrección de Ampacidad X factores de temperatura [A] | B51: =B50*B26*B25 -> 91.2
A52: Sirve la proteccion seleccionada? | B52: =IF(B51>=B38,"SI","NO") -> NO
A54: =IF(AND(B52="SI",B48="SI"), "OK",IF(OR(B52="NO",B48="NO"),"ERROR")) -> ERROR | B54: =IF(AND(B52="SI",B48="SI"), "La protección contra sobrecorrientes seleccionada funciona correctamente con el cable seleccionado",IF(OR(B52="NO",B48="NO"),"Realice un nuevo cálculo del cableado a utilizar o de la protección contra sobrecorrientes a utilizar")) -> Realice un nuevo cálculo del cableado a utilizar o de la protección contra sobrecorrientes a utilizar
A57: 5. CÁLCULO DEL CABLE DE PUESTA A TIERRA
A59: Material del cable de puesta a tierra | B59: COBRE
A60: Calibre minimo del cable de tierra [AWG] | B60: =VLOOKUP(INDEX('Cap 2 NTC'!A36:A47,MATCH(B38,'Cap 2 NTC'!A36:A47,-1)),'Cap 2 NTC'!A36:C47,MATCH('INV2_TABLERO FV_N'!B59,'Cap 2 NTC'!B34:C34,0)+1,FALSE) -> 8 | C60: Articulo 250-95 de la NTC 2050 y Articulo 15 Retie
A62: Calibre de cable depuesta a tierra seleccionado | B62: 8 AWG | C62: Seleccione un cable con calibre mayor o igual al calibre minimo del paso anterior
...

Sheet TABLERO FV_INTX
A1: Información de los inversores 1 | E1: Información de los inversores 2 | H1: Casillas de control
A2: Parametro | B2: Valor | E2: Parametro | F2: Valor | H2: =IF(AND(B17>=21,B17<=25),"21-25",IF(AND(B17>=26,B17<=30),"26-30",IF(AND(B17>=31,B17<=35),"31-35",IF(AND(B17>=36,B17<=40),"36-40",IF(AND(B17>=41,B17<=45),"41-45",IF(AND(B17>=46,B17<=50),"46-50",IF(AND(B17>=51,B17<=55),"51-55",IF(AND(B17>=56,B17<=60),"56-60",IF(AND(B17>=61,B17<=70),"61-70",IF(AND(B17>=71,B17<=80),"71-80","ERROR")))))))))) -> 21-25
A3: Fabricante | B3: ='INV1_TABLERO FV'!B3 -> Growatt | E3: Fabricante | H3: =IF(AND(B21>=1,B21<=3),1,IF(AND(B21>=4,B21<=6),"De 4 a 6",IF(AND(B21>=7,B21<=9),"De 7 a 9",IF(AND(B21>=10,B21<=20),"De 10 a 20",IF(AND(B21>=21,B21<=30),"De 21 a 30",IF(AND(B21>=31,B21<=40),"De 31 a 40",IF(B21>=41,"De 41 y más","ERROR"))))))) -> 1
A4: Referencia | B4: ='INV1_TABLERO FV'!B4 -> MIN10000 TL-X2 | E4: Referencia | H4: =IF(B18="COBRE",IF(OR(B19="90 ºC",B19="120 ºC"),INDEX('Cap 3 NTC'!P8:P37,MATCH(B30,'Cap 3 NTC'!P8:P37,-1)),IF(B19="75 ºC",INDEX('Cap 3 NTC'!O8:O37,MATCH(B30,'Cap 3 NTC'!O8:O37,-1)),INDEX('Cap 3 NTC'!N8:N37,MATCH(B30,'Cap 3 NTC'!N8:N37,-1)))),IF(OR(B19="90 ºC",B19="120 ºC"),INDEX('Cap 3 NTC'!S8:S37,MATCH(B30,'Cap 3 NTC'!S8:S37,-1)),IF(B19="75 ºC",INDEX('Cap 3 NTC'!R8:R37,MATCH(B30,'Cap 3 NTC'!R8:R37,-1)),INDEX('Cap 3 NTC'!Q8:Q37,MATCH(B30,'Cap 3 NTC'!Q8:Q37,-1))))) -> 55
A5: Potencia nominal [kW] | B5: ='INV1_TABLERO FV'!B5 -> 10 | E5: Potencia nominal [kW]
A6: Voltaje de salida [V AC] | B6: ='INV1_TABLERO FV'!B6 -> 220 | E6: Voltaje de salida [V AC]
A7: Corriente máxima de salida [A] | B7: ='INV1_TABLERO FV'!B7 -> 45.5 | E7: Corriente máxima de salida [A]
A8: Número de fases | B8: ='INV1_TABLERO FV'!B8 -> 2 | E8: Número de fases
A9: Número de inversores | B9: 1 | E9: Número de inversores
A11: 1. CORRIENTE MÁXIMA DEL CIRCUITO
A13: Imax [A] | B13: =B9*B7+F9*F7 -> 45.5
A15: 2. CÁLCULO DEL CALIBRE DEL CABLEADO
A17: Temperatura ambiente [°C] | B17: 24 | C17: Ingrese la temperatura maxima promedio del lugar de instalación
A18: Material del conductor a dimensionar | B18: COBRE
A19: Temperatura nominal del conductor [°C] | B19: 90 ºC
A20: Tipo de soporte de cables para el cálculo | B20: TUBERIA | C20: Por la Excepción del articulo 310.15 c). Cuando se obtengan dos capacidades de corriente distintas para partes seguidas de un circuito, se permite utilizar la mayor más allá del punto de transición, a la menor de las siguientes distanclas : 3,0 m o el 10 % de la longitud del circuito que da la capacidad de corriente mayor.
A21: Número de conductores portadores de corriente por la tubería | B21: 2 | C21: La salida del inversor es trifásico
A23: Calculo de Ampacidades
A24: Ampacidad minima A1 [A] | B24: =B13 -> 45.5 | C24: 220-10. b) NTC 2050
A26: Ft | B26: =IF(B18="COBRE",VLOOKUP(H2,'Cap 3 NTC'!A41:D50,MATCH(B19,'Cap 3 NTC'!A4:D4,0),FALSE),VLOOKUP(H2,'Cap 3 NTC'!A41:G50,MATCH(B19,'Cap 3 NTC'!E4:G4,0)+4,FALSE)) -> 1.04 | C26: Factor por temperatura ambiente | F26: 318-11 b) Los factores de corrección de la Sección 310, Nota 8.a) de las Notas a las Tablas de capacidad de corriente de 0 a 2 000 V, no se deben aplicar a la capacidad de corriente de los cables en bandejas.
A27: Fag | B27: =IF(B20="BANDEJA PORTACABLES",1,IF(AND(B21>=1,B21<=3),1,VLOOKUP(H3,'Cap 3 NTC'!J41:K46,2,FALSE))) -> 1 | C27: Factor por agrupación de conductores | F27: Ft en bandejas es 1,0 por articulo NTC 2050 318-11. b) Capacidad de corriente de los cables de 2 000 V o menos en las bandejas portacables
A28: Ampacidad 2 [A] | B28: =B13/(B26*B27) -> 43.75 | C28: tablas 310-16 a la 310-19 NTC 2050 | G28: REVISAR SI EN BANDEJA PORTACABLES SE CONSIDERA EL CONDUCTOR AL AIRE LIBRE Y SE ESCOGERIA LA AMPACIDAD DE LA TABLA 310-15, NO DE LA 310-16
A30: AMPACIDAD MINIMA DEL CABLE [A] | B30: =IF(B28>=B24,B28,B24) -> 45.5
A31: CALIBRE MINIMO DEL CABLE AWG | B31: =IF(B18="COBRE",IF(OR(B19="90 ºC",B19="120 ºC"),VLOOKUP(H4,'Cap 3 NTC'!P8:U37,6,FALSE),IF(B19="75 ºC",VLOOKUP(H4,'Cap 3 NTC'!O8:U37,7,FALSE),IF(B19="60 ºC",VLOOKUP(H4,'Cap 3 NTC'!N8:U37,8,FALSE)))),IF(OR(B19="90 ºC",B19="120 ºC"),VLOOKUP(H4,'Cap 3 NTC'!S8:U37,3,FALSE),IF(B19="75 ºC",VLOOKUP(H4,'Cap 3 NTC'!R8:U37,4,FALSE),IF(B19="60 ºC",VLOOKUP(H4,'Cap 3 NTC'!Q8:U37,5,FALSE))))) -> 8
A33: CALIBRE CABLE SELECCIONADO | B33: 6 AWG | C33: Seleccione un cable con calibre mayor o igual al calibre minimo del paso anterior
A35: 3. SELECCIÓN DE PROTECCIÓN DEL CIRCUITO
A37: Corriente minima de dispositivo Iocpd [A] | B37: =B13 -> 45.5 | C37: 210-22 c) de la NTC2050
A39: Corriente de corte de proteccion seleccionada [A] | B39: 50 | C39: Ingrese el valor de la corriente de corte del dispositivo de protección contra sobrecorrientes a instalar.
A41: =IF(B39>=B37,"OK","ERROR") -> OK | B41: =IF(A41="OK","Protección seleccionada es mayor a la corriente minima de OCPD",IF(A41="ERROR","La protección seleccionada debe ser mayor a la corriente minima de OCPD")) -> Protección seleccionada es mayor a la corriente minima de OCPD | F41: artículo 27.4.3 c) del RETIE
A44: 4. VALIDACION DE LA PROTECCIÓN CONTRA SOBRECORRIENTES
A46: Temperatura nominal de funcionamiento de los conectores [°C] | B46: 60 ºC | C46: Seleccione la temperatura nominal de los conectores de los equipos. Todos los puntos de conexión, cables y equipos en una instalación eléctrica deberán soportar 60°C si conducen 100A o menos, si conducen mas de 100A podrán soportar 75°C. Sección 110-14 C de la NTC2050 y el articulo 20.2.9 f) del retie
A48: =CONCATENATE("Ampacidad del cable seleccionado @", B46, " [A]") -> Ampacidad del cable seleccionado @60 ºC [A] | B48: =IF(B18="COBRE",IF(OR(B46="90 ºC",B46="120 ºC"),VLOOKUP(B33,'Cap 3 NTC'!M8:P37,4,FALSE),IF(B46="75 ºC",VLOOKUP(B33,'Cap 3 NTC'!M8:O37,3,FALSE),IF(B46="60 ºC",VLOOKUP(B33,'Cap 3 NTC'!M8:N37,2,FALSE)))),IF(OR(B46="90 ºC",B46="120 ºC"),VLOOKUP(B33,'Cap 3 NTC'!M8:S37,7,FALSE),IF(B46="75 ºC",VLOOKUP(B33,'Cap 3 NTC'!M8:R37,6,FALSE),IF(B46="60 ºC",VLOOKUP(B33,'Cap 3 NTC'!M8:Q37,5,FALSE))))) -> 55
A49: Sirve la proteccion seleccionada? | B49: =IF(B48>=B39,"SI","NO") -> SI | C49: Según articulo 110-14.c) de la NTC 20150 y articulo 20.2.9 f del RETIE
A51: =CONCATENATE("Ampacidad del cable seleccionado temperatura nominal @", B19, " [A]") -> Ampacidad del cable seleccionado temperatura nominal @90 ºC [A] | B51: =IF(B18="COBRE",IF(OR(B19="90 ºC",B19="120 ºC"),VLOOKUP(B33,'Cap 3 NTC'!M8:P37,4,FALSE),IF(B19="75 ºC",VLOOKUP(B33,'Cap 3 NTC'!M8:O37,3,FALSE),IF(B19="60 ºC",VLOOKUP(B33,'Cap 3 NTC'!M8:N37,2,FALSE)))),IF(OR(B19="90 ºC",B19="120 ºC"),VLOOKUP(B33,'Cap 3 NTC'!M8:S37,7,FALSE),IF(B19="75 ºC",VLOOKUP(B33,'Cap 3 NTC'!M8:R37,6,FALSE),IF(B19="60 ºC",VLOOKUP(B33,'Cap 3 NTC'!M8:Q37,5,FALSE))))) -> 75
A52: Corrección de Ampacidad X factores de temperatura [A] | B52: =B51*B27*B26 -> 78
A53: Sirve la proteccion seleccionada? | B53: =IF(B52>=B39,"SI","NO") -> SI
A55: =IF(AND(B53="SI",B49="SI"), "OK",IF(OR(B53="NO",B49="NO"),"ERROR")) -> OK | B55: =IF(AND(B53="SI",B49="SI"), "La protección contra sobrecorrientes seleccionada funciona correctamente con el cable seleccionado",IF(OR(B53="NO",B49="NO"),"Realice un nuevo cálculo del cableado a utilizar o de la protección contra sobrecorrientes a utilizar")) -> La protección contra sobrecorrientes seleccionada funciona correctamente con el cable seleccionado
A58: 5. CÁLCULO DEL CABLE DE PUESTA A TIERRA
A60: Material del cable de puesta a tierra | B60: COBRE
A61: Calibre minimo del cable de tierra [AWG] | B61: =VLOOKUP(INDEX('Cap 2 NTC'!A36:A47,MATCH(B39,'Cap 2 NTC'!A36:A47,-1)),'Cap 2 NTC'!A36:C47,MATCH('TABLERO FV_INTX'!B60,'Cap 2 NTC'!B34:C34,0)+1,FALSE) -> 10 | C61: Articulo 250-95 de la NTC 2050 y Articulo 15 Retie
...

Sheet Regulación_Voltaje
W1: FP | Y1: 1 | AD1: FP | AF1: 1 | AK1: FP | AM1: 1
W2: Tipo de tuberia para cálculo de impedancia | Y2: CONDUIT METAL | AD2: Tipo de tuberia para cálculo de impedancia | AF2: CONDUIT METAL | AK2: Tipo de tuberia para cálculo de impedancia | AM2: CONDUIT METAL
A3: STRING | B3: DISTANCIA ENTRE FV E INVERSOR [m] | C3: CORRIENTE DE CARGA (Impp) [A] | D3: CANTIDAD DE MÓDULOS DEL STRING | E3: VOLTAJE DEL STRING (Vmpp) [V DC] | F3: MATERIAL DEL CONDUCTOR | G3: CALIBRE CONDUCTOR | H3: RESISTENCIA OHM/KM @75ºC | I3: % REG | J3: COMBINER BOX | K3: LONGITUD ENTRE CB E INVERSORES [m] | L3: NUMERO DE CADENAS EN PARALELO | M3: CORRIENTE DE CARGA [A] | N3: VOLTAJE STRING [V] | O3: CALIBRE CONDUCTOR DC | P3: RESISTIVIDAD [Ohm/km] | Q3: % REG | R3: %REG TOTAL DC | S3: INVERSOR | T3: LONGITUD ENTRE INVERSORES Y TABLERO FV AC [m] | U3: CORRIENTE DE CARGA [A] | V3: TENSIÓN ACOMETIDA [V] | W3: MATERIAL DEL CONDUCTOR | X3: CALIBRE CONDUCTOR | Y3: IMPEDANCIA EQUIVALENTE [Ohm/km] | Z3: % REG | AA3: LONGITUD ENTRE TABLERO FV AC Y TABLERO PPAL [m] | AB3: CORRIENTE DE CARGA [A] | AC3: VOLTAJE ACOMETIDA [V] | AD3: MATERIAL DEL CONDUCTOR | AE3: CALIBRE CONDUCTOR | AF3: IMPEDANCIA EQUIVALENTE [Ohm/km] | AG3: % REG | AH3: LONGITUD TRANSFORMADOR Y TABLERO PRINCIPAL [m] | AI3: CORRIENTE DE CARGA [A] | AJ3: VOLTAJE ACOMETIDA [V] | AK3: MATERIAL DEL CONDUCTOR | AL3: CALIBRE CONDUCTOR | AM3: IMPEDANCIA EQUIVALENTE [Ohm/km] | AN3: % REG | AO3: % REG TOTAL AC | AP3: % REG TOTAL SISTEMA
A4: 1.1.1 | B4: 20 | C4: =PV_INV_STRING!$B$9 -> 13.03 | D4: 7 | E4: =D4*PV_INV_STRING!$B$6 -> 363.37 | F4: COBRE | G4: 4 mm² | H4: =IF(A4="","",IF(F4="COBRE",VLOOKUP(G4,'Cap 9 NTC'!$M$15:$V$35,10,FALSE))) -> 6.73 | I4: =IF(A4="",0,(2*C4*B4/1000*H4)/E4) -> 0.00965318 | J4: 1 | K4: 0 | L4: 0 | M4: =IF(J4="","",L4*C4) -> 0 | N4: =IF(J4="","",E4) -> 363.37 | O4: 4 mm² | P4: =IF(J4="","",IF(F4="COBRE",VLOOKUP(O4,'Cap 9 NTC'!$M$15:$V$35,10,FALSE))) -> 6.73 | Q4: =IF(J4="",0,(2*M4*(K4/1000)*P4)/N4) -> 0 | R4: =Q4+MAX(I4:I5) -> 0.00965318 | S4: 1 | T4: 2.5 | U4: ='INV1_TABLERO FV'!$B$7 -> 45.5 | V4: ='INV1_TABLERO FV'!$B$6 -> 220 | W4: COBRE | X4: 10 AWG | Y4: =(((IF(W4="COBRE",VLOOKUP(X4,'Cap 9 NTC'!N44:S64,MATCH($Y$2,'Cap 9 NTC'!R43:S43,0)+4,FALSE),VLOOKUP(X4,'Cap 9 NTC'!N44:U64,MATCH($Y$2,'Cap 9 NTC'!T43:U43,0)+6,FALSE)))*$Y$1)+(VLOOKUP(X4,'Cap 9 NTC'!N44:Q64,MATCH($Y$2,'Cap 9 NTC'!P43:Q43,0)+2,FALSE))*SIN(ACOS($Y$1))) -> 3.94 | Z4: =IF(S4="",0,(SQRT(3)*T4/1000*U4*Y4)/V4) -> 0.003528463 | AA4: 2 | AB4: =SUM(U4:U7) -> 45.5 | AC4: =V4 -> 220 | AD4: COBRE | AE4: 10 AWG | AF4: =(((IF(AD4="COBRE",VLOOKUP(AE4,'Cap 9 NTC'!N44:S64,MATCH(AF2,'Cap 9 NTC'!R43:S43,0)+4,FALSE),VLOOKUP(AE4,'Cap 9 NTC'!N44:U64,MATCH(AF2,'Cap 9 NTC'!T43:U43,0)+6,FALSE)))*$AF$1)+(VLOOKUP(AE4,'Cap 9 NTC'!N44:Q64,MATCH(AF2,'Cap 9 NTC'!P43:Q43,0)+2,FALSE))*SIN(ACOS($AF$1))) -> 3.94 | AG4: =(SQRT(3)*AA4/1000*AB4*AF4)/AC4 -> 0.0028227704 | AH4: 5 | AI4: =#REF! -> #REF! | AJ4: =#REF! -> #REF! | AK4: COBRE | AL4: 4/0 AWG | AM4: =(((IF(AK4="COBRE",VLOOKUP(AL4,'Cap 9 NTC'!N44:S64,MATCH(AM2,'Cap 9 NTC'!R43:S43,0)+4,FALSE),VLOOKUP(AL4,'Cap 9 NTC'!N44:U64,MATCH(AM2,'Cap 9 NTC'!T43:U43,0)+6,FALSE)))*$AM$1)+(VLOOKUP(AL4,'Cap 9 NTC'!N44:Q64,MATCH(AM2,'Cap 9 NTC'!P43:Q43,0)+2,FALSE))*SIN(ACOS($AM$1))) -> 0.207 | AN4: =(SQRT(3)*AH4/1000*AI4*AM4)/AJ4 -> #REF! | AO4: =IF(S4="",0,AG4+Z4) -> 0.0063512335 | AP4: =AO4+MAX(Z4:Z7)+MAX(R4:R7) -> 0.019532876
A5: 1.2.1 | B5: 20 | C5: =PV_INV_STRING!$B$9 -> 13.03 | D5: 9 | E5: =D5*PV_INV_STRING!$B$6 -> 467.19 | F5: COBRE | G5: 4 mm² | H5: =IF(A5="","",IF(F5="COBRE",VLOOKUP(G5,'Cap 9 NTC'!$M$15:$V$35,10,FALSE))) -> 6.73 | I5: =IF(A5="",0,(2*C5*B5/1000*H5)/E5) -> 0.0075080289 | R5: =Q5+MAX(I5:I6) -> 0.00965318
A6: 2.1.1 | B6: 20 | C6: =PV_INV_STRING!$B$9 -> 13.03 | D6: 7 | E6: =D6*PV_INV_STRING!$B$6 -> 363.37 | F6: COBRE | G6: 4 mm² | H6: =IF(A6="","",IF(F6="COBRE",VLOOKUP(G6,'Cap 9 NTC'!$M$15:$V$35,10,FALSE))) -> 6.73 | I6: =IF(A6="",0,(2*C6*B6/1000*H6)/E6) -> 0.00965318 | J6: 2 | K6: 0 | L6: 0 | M6: =IF(J6="","",L6*C6) -> 0 | N6: =IF(J6="","",E6) -> 363.37 | O6: 4 mm² | P6: =IF(J6="","",IF(F6="COBRE",VLOOKUP(O6,'Cap 9 NTC'!$M$15:$V$35,10,FALSE))) -> 6.73 | Q6: =IF(J6="",0,(2*M6*(K6/1000)*P6)/N6) -> 0 | R6: =Q6+MAX(I6) -> 0.00965318
A7: 2.2.1 | B7: 20 | C7: =PV_INV_STRING!$B$9 -> 13.03 | D7: 8 | E7: 428.8 | F7: COBRE | G7: 4 mm² | H7: =IF(A7="","",IF(F7="COBRE",VLOOKUP(G7,'Cap 9 NTC'!$M$15:$V$35,10,FALSE))) -> 6.73 | I7: =IF(A7="",0,(2*C7*B7/1000*H7)/E7) -> 0.0081802146
A9: STRING | B9: % REG DC | C9: INVERSOR | D9: % REG AC | E9: % REGULACION TOTAL
A10: 1.1.1 | B10: =I4 -> 0.00965318 | C10: 1 | D10: =Z4+AG4 -> 0.0063512335 | E10: =D10+B10 -> 0.016004413
A11: 1.1.2 | B11: =I5 -> 0.0075080289 | C11: 1 | E11: =D11+B11 -> 0.0075080289

Sheet Perdidas P_E 
A1: Ubicación | B1: Anserma | X1: FP | Z1: 1 | AF1: FP | AH1: 1
A2: HPS [h] | B2: 4 | D2: De mapa de radiación del IDEAM | X2: Tipo de tuberia para cálculo de impedancia | Z2: CONDUIT METAL | AF2: Tipo de tuberia para cálculo de impedancia | AH2: CONDUIT METAL
A3: STRING | B3: DISTANCIA ENTRE FV E INVERSOR [m] | C3: CORRIENTE DE CARGA (Impp) [A] | D3: CANTIDAD DE MÓDULOS DEL STRING | E3: VOLTAJE DEL STRING (Vmpp) [V DC] | F3: MATERIAL DEL CONDUCTOR | G3: CALIBRE CONDUCTOR | H3: RESISTENCIA OHM/KM @75ºC | I3: PÉRDIDAS DE POTENCIA [W] | J3: PÉRDIDAS DE ENERGIA ENTRE FV E INVERSOR [kWh/mes] | K3: COMBINER BOX | L3: LONGITUD ENTRE CB E INVERSORES [m] | M3: NUMERO DE CADENAS EN PARALELO | N3: CORRIENTE DE CARGA [A] | O3: VOLTAJE STRING [V] | P3: CALIBRE CONDUCTOR DC | Q3: RESISTIVIDAD [Ohm/km] | R3: % REG | T3: INVERSOR | U3: LONGITUD ENTRE INVERSORES Y TABLERO FV AC [m] | V3: CORRIENTE DE CARGA [A] | W3: TENSIÓN ACOMETIDA [V] | X3: MATERIAL DEL CONDUCTOR | Y3: CALIBRE CONDUCTOR | Z3: IMPEDANCIA EQUIVALENTE [Ohm/km] | AA3: PÉRDIDAS DE POTENCIA [W] | AB3: PÉRDIDAS DE ENERGIA INV - TABLERO FV AC [kWh/mes] | AC3: LONGITUD ENTRE TABLERO FV AC Y TABLERO PPAL [m] | AD3: CORRIENTE DE CARGA [A] | AE3: VOLTAJE ACOMETIDA [V] | AF3: MATERIAL DEL CONDUCTOR | AG3: CALIBRE CONDUCTOR | AH3: IMPEDANCIA EQUIVALENTE [Ohm/km] | AI3: PÉRDIDAS DE POTENCIA [W] | AJ3: PÉRDIDAS DE ENERGIA TABLERO FV AC - TABLERO PPAL [kWh/mes]
